Workbook

Sheet Q2
B2: Portfolio Information
B3: Maturity (Years) | C3: US1 | D3: US2 | E3: US3 | F3: UK1 | G3: UK2 | H3: UK3
B4: PV01($) Vector (q) | C4: 1000 | D4: -1500 | E4: 2000 | F4: 800 | G4: 900 | H4: -750
B5: Volatility (bps) | C5: 100 | D5: 80 | E5: 70 | F5: 85 | G5: 75 | H5: 65
B7: Correlation Matrix
B8: 1 | C8: 0.95 | D8: 0.9 | E8: 0.7 | F8: 0.67 | G8: 0.62
B9: 0.95 | C9: 1 | D9: 0.97 | E9: 0.65 | F9: 0.75 | G9: 0.75
B10: 0.9 | C10: 0.97 | D10: 1 | E10: 0.6 | F10: 0.79 | G10: 0.8
B11: 0.7 | C11: 0.65 | D11: 0.6 | E11: 1 | F11: 0.98 | G11: 0.95
B12: 0.67 | C12: 0.75 | D12: 0.79 | E12: 0.98 | F12: 1 | G12: 0.99
B13: 0.62 | C13: 0.75 | D13: 0.8 | E13: 0.95 | F13: 0.99 | G13: 1
C17: Covariance (Annual)
B18: Vol (bps) | D18: 100 | E18: 80 | F18: 70 | G18: 85 | H18: 75 | I18: 65
D19: {=TRANSPOSE(C20:C25)} -> US1 | E19: US2 | F19: US3 | G19: UK1 | H19: UK2 | I19: UK3
B20: {=TRANSPOSE(D18:I18)} -> 100 | C20: US1 | D20: =$B20*D$18 -> 10000 | E20: =$B20*E$18*C8 -> 7600 | F20: =$B20*F$18*D8 -> 6300 | G20: =$B20*G$18*E8 -> 5950 | H20: =$B20*H$18*F8 -> 5025 | I20: =$B20*I$18*G8 -> 4030
B21: 80 | C21: US2 | D21: {=TRANSPOSE(E20:I20)} -> 7600 | E21: =$B21*E$18 -> 6400 | F21: =$B21*F$18*D9 -> 5432 | G21: =$B21*G$18*E9 -> 4420 | H21: =$B21*H$18*F9 -> 4500 | I21: =$B21*I$18*G9 -> 3900
B22: 70 | C22: US3 | D22: 6300 | E22: {=TRANSPOSE(F21:I21)} -> 5432 | F22: =$B22*F$18 -> 4900 | G22: =$B22*G$18*E10 -> 3570 | H22: =$B22*H$18*F10 -> 4147.5 | I22: =$B22*I$18*G10 -> 3640
B23: 85 | C23: UK1 | D23: 5950 | E23: 4420 | F23: {=TRANSPOSE(G22:I22)} -> 3570 | G23: =$B23*G$18 -> 7225 | H23: =$B23*H$18*F11 -> 6247.5 | I23: =$B23*I$18*G11 -> 5248.75
B24: 75 | C24: UK2 | D24: 5025 | E24: 4500 | F24: 4147.5 | G24: {=TRANSPOSE(H23:I23)} -> 6247.5 | H24: =$B24*H$18 -> 5625 | I24: =$B24*I$18*G12 -> 4826.25
B25: 65 | C25: UK3 | D25: 4030 | E25: 3900 | F25: 3640 | G25: 5248.75 | H25: =I24 -> 4826.25 | I25: =$B25*I$18 -> 4225
B28: US COVARIANCE | F28: UK COVARIANCE | J28: US-UK COVARIANCE
B29: {=D20:F22} -> 10000 | C29: 7600 | D29: 6300 | F29: {=G23:I25} -> 7225 | G29: 6247.5 | H29: 5248.75 | J29: {=G20:I22} -> 5950 | K29: 5025 | L29: 4030
B30: 7600 | C30: 6400 | D30: 5432 | F30: 6247.5 | G30: 5625 | H30: 4826.25 | J30: 4420 | K30: 4500 | L30: 3900
B31: 6300 | C31: 5432 | D31: 4900 | F31: 5248.75 | G31: 4826.25 | H31: 4225 | J31: 3570 | K31: 4147.5 | L31: 3640
B35: 1% Total Risk Factor VaR | E35: 1% US Interest Rate VaR | H35: 1% UK Interest Rate VaR
B36: q'Wq | C36: {=MMULT(C4:H4,MMULT(D20:I25,TRANSPOSE(C4:H4)))} -> 35519275000 | E36: q'Wq | F36: {=MMULT(C4:E4,MMULT(_xlfn.ANCHORARRAY(B29),TRANSPOSE(C4:E4)))} -> 13808000000 | H36: q'Wq | I36: {=MMULT(F4:H4,MMULT(_xlfn.ANCHORARRAY(F29),TRANSPOSE(F4:H4)))} -> 7739275000
B37: Invers Normal | C37: =_xlfn.NORM.S.INV(0.99) -> 2.3263479 | E37: Invers Normal | F37: =_xlfn.NORM.S.INV(0.99) -> 2.3263479 | H37: Invers Normal | I37: =_xlfn.NORM.S.INV(0.99) -> 2.3263479
B38: Annual VaR | C38: =C37*SQRT(C36) -> 438436.5 | E38: Annual VaR | F38: =F37*SQRT(F36) -> 273363.2 | H38: Annual VaR | I38: =I37*SQRT(I36) -> 204656.15
B39: 10-day VaR | C39: =C38*SQRT(10/250) -> 87687.3 | E39: 10-day VaR | F39: =F38*SQRT(10/250) -> 54672.64 | H39: 10-day VaR | I39: =I38*SQRT(10/250) -> 40931.23
B41: Sum of Stand Alones | C41: =F39+I39 -> 95603.869
C44: Wq | D44: g(q)
B45: US1 | C45: {=MMULT(D20:I25,TRANSPOSE(C4:H4))} -> 17460000 | D45: =_xlfn.NORM.S.INV(0.99)*C45/SQRT($C$36) -> 215.51964
B46: US2 | C46: 13525000 | D46: =_xlfn.NORM.S.INV(0.99)*C46/SQRT($C$36) -> 166.94749
B47: US3 | C47: 11810750 | D47: =_xlfn.NORM.S.INV(0.99)*C47/SQRT($C$36) -> 145.78743
B48: UK1 | C48: 13926188 | D48: =_xlfn.NORM.S.INV(0.99)*C48/SQRT($C$36) -> 171.89959
B49: UK2 | C49: 13010812 | D49: =_xlfn.NORM.S.INV(0.99)*C49/SQRT($C$36) -> 160.60055
B50: UK3 | C50: 10833875 | D50: =_xlfn.NORM.S.INV(0.99)*C50/SQRT($C$36) -> 133.72926
B53: US Marginal VaR
B54: Annual VaR | C54: {=MMULT(C4:E4,D45:D47)} -> 256673.27
B55: 10-day VaR | C55: =C54*SQRT(10/250) -> 51334.655
...

Sheet Q3 Returns
A1: Dates | B1: 1m | C1: 2m | D1: 3m | E1: 4m | F1: 5m | G1: 6m | H1: 7m | I1: 8m | J1: 9m | K1: 10m | L1: 11m | M1: 12m | N1: 13m | O1: 14m | P1: 15m | Q1: 16m | R1: 17m | S1: 18m | T1: 19m | U1: 20m | V1: 21m | W1: 22m | X1: 23m | Y1: 24m | Z1: 25m | AA1: 26m | AB1: 27m | AC1: 28m | AD1: 29m | AE1: 30m | AF1: 31m | AG1: 32m | AH1: 33m | AI1: 34m | AJ1: 35m | AK1: 36m | AL1: 37m | AM1: 38m | AN1: 39m | AO1: 40m | AP1: 41m | AQ1: 42m | AR1: 43m | AS1: 44m | AT1: 45m | AU1: 46m | AV1: 47m | AW1: 48m | AX1: 49m | AY1: 50m | AZ1: 51m | BA1: 52m | BB1: 53m | BC1: 54m | BD1: 55m | BE1: 56m | BF1: 57m | BG1: 58m | BH1: 59m | BI1: 60m
A2: 39085 | B2: =('[1]Short Spot'!B3-'[1]Short Spot'!B2)*100 -> -0.1355791 | C2: =('[1]Short Spot'!C3-'[1]Short Spot'!C2)*100 -> -0.33542159 | D2: =('[1]Short Spot'!D3-'[1]Short Spot'!D2)*100 -> -0.17634692 | E2: =('[1]Short Spot'!E3-'[1]Short Spot'!E2)*100 -> -0.016726879 | F2: =('[1]Short Spot'!F3-'[1]Short Spot'!F2)*100 -> 0.10600612 | G2: =('[1]Short Spot'!G3-'[1]Short Spot'!G2)*100 -> 0.19626928 | H2: =('[1]Short Spot'!H3-'[1]Short Spot'!H2)*100 -> 0.26813013 | I2: =('[1]Short Spot'!I3-'[1]Short Spot'!I2)*100 -> 0.33306084 | ... BI2: =('[1]Short Spot'!BI3-'[1]Short Spot'!BI2)*100 -> 1.2936828
A3: 39086 | B3: =('[1]Short Spot'!B4-'[1]Short Spot'!B3)*100 -> 0.1476462 | C3: =('[1]Short Spot'!C4-'[1]Short Spot'!C3)*100 -> 0.32902134 | D3: =('[1]Short Spot'!D4-'[1]Short Spot'!D3)*100 -> 0.5289926 | E3: =('[1]Short Spot'!E4-'[1]Short Spot'!E3)*100 -> 0.72484614 | F3: =('[1]Short Spot'!F4-'[1]Short Spot'!F3)*100 -> 0.88711823 | G3: =('[1]Short Spot'!G4-'[1]Short Spot'!G3)*100 -> 1.0054633 | H3: =('[1]Short Spot'!H4-'[1]Short Spot'!H3)*100 -> 1.0760249 | I3: =('[1]Short Spot'!I4-'[1]Short Spot'!I3)*100 -> 1.0961554 | ... BI3: =('[1]Short Spot'!BI4-'[1]Short Spot'!BI3)*100 -> -1.3625493
A4: 39087 | B4: =('[1]Short Spot'!B5-'[1]Short Spot'!B4)*100 -> 0.91653761 | C4: =('[1]Short Spot'!C5-'[1]Short Spot'!C4)*100 -> 0.8542341 | D4: =('[1]Short Spot'!D5-'[1]Short Spot'!D4)*100 -> 0.19244155 | E4: =('[1]Short Spot'!E5-'[1]Short Spot'!E4)*100 -> -0.37772357 | F4: =('[1]Short Spot'!F5-'[1]Short Spot'!F4)*100 -> -0.69769445 | G4: =('[1]Short Spot'!G5-'[1]Short Spot'!G4)*100 -> -0.77348963 | H4: =('[1]Short Spot'!H5-'[1]Short Spot'!H4)*100 -> -0.6648669 | I4: =('[1]Short Spot'!I5-'[1]Short Spot'!I4)*100 -> -0.44798739 | ... BI4: =('[1]Short Spot'!BI5-'[1]Short Spot'!BI4)*100 -> 2.2819549
A5: 39090 | B5: =('[1]Short Spot'!B6-'[1]Short Spot'!B5)*100 -> 0.50992443 | C5: =('[1]Short Spot'!C6-'[1]Short Spot'!C5)*100 -> 0.83884723 | D5: =('[1]Short Spot'!D6-'[1]Short Spot'!D5)*100 -> 0.91538757 | E5: =('[1]Short Spot'!E6-'[1]Short Spot'!E5)*100 -> 1.0079882 | F5: =('[1]Short Spot'!F6-'[1]Short Spot'!F5)*100 -> 1.1199828 | G5: =('[1]Short Spot'!G6-'[1]Short Spot'!G5)*100 -> 1.2350383 | H5: =('[1]Short Spot'!H6-'[1]Short Spot'!H5)*100 -> 1.3337407 | I5: =('[1]Short Spot'!I6-'[1]Short Spot'!I5)*100 -> 1.4010435 | ... BI5: =('[1]Short Spot'!BI6-'[1]Short Spot'!BI5)*100 -> -0.74819168
A6: 39091 | B6: =('[1]Short Spot'!B7-'[1]Short Spot'!B6)*100 -> 1.3965079 | C6: =('[1]Short Spot'!C7-'[1]Short Spot'!C6)*100 -> 1.8608548 | D6: =('[1]Short Spot'!D7-'[1]Short Spot'!D6)*100 -> 1.8250937 | E6: =('[1]Short Spot'!E7-'[1]Short Spot'!E6)*100 -> 1.7200119 | F6: =('[1]Short Spot'!F7-'[1]Short Spot'!F6)*100 -> 1.6062793 | G6: =('[1]Short Spot'!G7-'[1]Short Spot'!G6)*100 -> 1.5009965 | H6: =('[1]Short Spot'!H7-'[1]Short Spot'!H6)*100 -> 1.4099165 | I6: =('[1]Short Spot'!I7-'[1]Short Spot'!I6)*100 -> 1.3348461 | ... BI6: =('[1]Short Spot'!BI7-'[1]Short Spot'!BI6)*100 -> 1.4428825
A7: 39092 | B7: =('[1]Short Spot'!B8-'[1]Short Spot'!B7)*100 -> 1.2651203 | C7: =('[1]Short Spot'!C8-'[1]Short Spot'!C7)*100 -> 0.89228645 | D7: =('[1]Short Spot'!D8-'[1]Short Spot'!D7)*100 -> 0.70153815 | E7: =('[1]Short Spot'!E8-'[1]Short Spot'!E7)*100 -> 0.52932583 | F7: =('[1]Short Spot'!F8-'[1]Short Spot'!F7)*100 -> 0.41889009 | G7: =('[1]Short Spot'!G8-'[1]Short Spot'!G7)*100 -> 0.37625589 | H7: =('[1]Short Spot'!H8-'[1]Short Spot'!H7)*100 -> 0.38721188 | I7: =('[1]Short Spot'!I8-'[1]Short Spot'!I7)*100 -> 0.42352918 | ... BI7: =('[1]Short Spot'!BI8-'[1]Short Spot'!BI7)*100 -> 0.43834155
A8: 39093 | B8: =('[1]Short Spot'!B9-'[1]Short Spot'!B8)*100 -> 0.42036328 | C8: =('[1]Short Spot'!C9-'[1]Short Spot'!C8)*100 -> 0.80224686 | D8: =('[1]Short Spot'!D9-'[1]Short Spot'!D8)*100 -> 2.2648538 | E8: =('[1]Short Spot'!E9-'[1]Short Spot'!E8)*100 -> 3.7752033 | F8: =('[1]Short Spot'!F9-'[1]Short Spot'!F8)*100 -> 5.05562 | G8: =('[1]Short Spot'!G9-'[1]Short Spot'!G8)*100 -> 6.0748704 | H8: =('[1]Short Spot'!H9-'[1]Short Spot'!H8)*100 -> 6.884875 | I8: =('[1]Short Spot'!I9-'[1]Short Spot'!I8)*100 -> 7.5636639 | ... BI8: =('[1]Short Spot'!BI9-'[1]Short Spot'!BI8)*100 -> 7.8440171
A9: 39094 | B9: =('[1]Short Spot'!B10-'[1]Short Spot'!B9)*100 -> 19.309115 | C9: =('[1]Short Spot'!C10-'[1]Short Spot'!C9)*100 -> 17.489912 | D9: =('[1]Short Spot'!D10-'[1]Short Spot'!D9)*100 -> 15.926536 | E9: =('[1]Short Spot'!E10-'[1]Short Spot'!E9)*100 -> 14.689385 | F9: =('[1]Short Spot'!F10-'[1]Short Spot'!F9)*100 -> 13.753038 | G9: =('[1]Short Spot'!G10-'[1]Short Spot'!G9)*100 -> 13.046528 | H9: =('[1]Short Spot'!H10-'[1]Short Spot'!H9)*100 -> 12.473642 | I9: =('[1]Short Spot'!I10-'[1]Short Spot'!I9)*100 -> 11.92874 | ... BI9: =('[1]Short Spot'!BI10-'[1]Short Spot'!BI9)*100 -> 4.1028389
A10: 39097 | B10: =('[1]Short Spot'!B11-'[1]Short Spot'!B10)*100 -> 1.2836439 | C10: =('[1]Short Spot'!C11-'[1]Short Spot'!C10)*100 -> 1.1181381 | D10: =('[1]Short Spot'!D11-'[1]Short Spot'!D10)*100 -> 0.91615628 | E10: =('[1]Short Spot'!E11-'[1]Short Spot'!E10)*100 -> 0.77516954 | F10: =('[1]Short Spot'!F11-'[1]Short Spot'!F10)*100 -> 0.66528832 | G10: =('[1]Short Spot'!G11-'[1]Short Spot'!G10)*100 -> 0.56966577 | H10: =('[1]Short Spot'!H11-'[1]Short Spot'!H10)*100 -> 0.47940372 | I10: =('[1]Short Spot'!I11-'[1]Short Spot'!I10)*100 -> 0.39204214 | ... BI10: =('[1]Short Spot'!BI11-'[1]Short Spot'!BI10)*100 -> -0.77716053
A11: 39098 | B11: =('[1]Short Spot'!B12-'[1]Short Spot'!B11)*100 -> -0.76121993 | C11: =('[1]Short Spot'!C12-'[1]Short Spot'!C11)*100 -> -0.10316868 | D11: =('[1]Short Spot'!D12-'[1]Short Spot'!D11)*100 -> 0.0059040495 | E11: =('[1]Short Spot'!E12-'[1]Short Spot'!E11)*100 -> 0.0052243734 | F11: =('[1]Short Spot'!F12-'[1]Short Spot'!F11)*100 -> -0.018821899 | G11: =('[1]Short Spot'!G12-'[1]Short Spot'!G11)*100 -> -0.039919874 | H11: =('[1]Short Spot'!H12-'[1]Short Spot'!H11)*100 -> -0.053969914 | I11: =('[1]Short Spot'!I12-'[1]Short Spot'!I11)*100 -> -0.067869254 | ... BI11: =('[1]Short Spot'!BI12-'[1]Short Spot'!BI11)*100 -> -0.63528298
A12: 39099 | B12: =('[1]Short Spot'!B13-'[1]Short Spot'!B12)*100 -> 0.03149402 | C12: =('[1]Short Spot'!C13-'[1]Short Spot'!C12)*100 -> 0.23583598 | D12: =('[1]Short Spot'!D13-'[1]Short Spot'!D12)*100 -> 0.63070854 | E12: =('[1]Short Spot'!E13-'[1]Short Spot'!E12)*100 -> 0.9751867 | F12: =('[1]Short Spot'!F13-'[1]Short Spot'!F12)*100 -> 1.2677892 | G12: =('[1]Short Spot'!G13-'[1]Short Spot'!G12)*100 -> 1.5236453 | H12: =('[1]Short Spot'!H13-'[1]Short Spot'!H12)*100 -> 1.7578532 | I12: =('[1]Short Spot'!I13-'[1]Short Spot'!I12)*100 -> 1.9787376 | ... BI12: =('[1]Short Spot'!BI13-'[1]Short Spot'!BI12)*100 -> 2.6827959
A13: 39100 | B13: =('[1]Short Spot'!B14-'[1]Short Spot'!B13)*100 -> 1.7387431 | C13: =('[1]Short Spot'!C14-'[1]Short Spot'!C13)*100 -> 2.849756 | D13: =('[1]Short Spot'!D14-'[1]Short Spot'!D13)*100 -> 3.3320357 | E13: =('[1]Short Spot'!E14-'[1]Short Spot'!E13)*100 -> 3.6047154 | F13: =('[1]Short Spot'!F14-'[1]Short Spot'!F13)*100 -> 3.765641 | G13: =('[1]Short Spot'!G14-'[1]Short Spot'!G13)*100 -> 3.8523075 | H13: =('[1]Short Spot'!H14-'[1]Short Spot'!H13)*100 -> 3.879076 | I13: =('[1]Short Spot'!I14-'[1]Short Spot'!I13)*100 -> 3.8478064 | ... BI13: =('[1]Short Spot'!BI14-'[1]Short Spot'!BI13)*100 -> 1.5217024
... A253: 39447 | B253: =('[1]Short Spot'!B254-'[1]Short Spot'!B253)*100 -> -0.38400104 | C253: =('[1]Short Spot'!C254-'[1]Short Spot'!C253)*100 -> -0.36599457 | D253: =('[1]Short Spot'!D254-'[1]Short Spot'!D253)*100 -> -0.25285563 | E253: =('[1]Short Spot'!E254-'[1]Short Spot'!E253)*100 -> -0.23888139 | F253: =('[1]Short Spot'!F254-'[1]Short Spot'!F253)*100 -> -0.35312539 | G253: =('[1]Short Spot'!G254-'[1]Short Spot'!G253)*100 -> -0.57374915 | H253: =('[1]Short Spot'!H254-'[1]Short Spot'!H253)*100 -> -0.86627751 | I253: =('[1]Short Spot'!I254-'[1]Short Spot'!I253)*100 -> -1.2061528 | ... BI253: =('[1]Short Spot'!BI254-'[1]Short Spot'!BI253)*100 -> -4.9462681

Sheet Q3 Covariance
B1: 1m | C1: 2m | D1: 3m | E1: 4m | F1: 5m | G1: 6m | H1: 7m | I1: 8m | J1: 9m | K1: 10m | L1: 11m | M1: 12m | N1: 13m | O1: 14m | P1: 15m | Q1: 16m | R1: 17m | S1: 18m | T1: 19m | U1: 20m | V1: 21m | W1: 22m | X1: 23m | Y1: 24m | Z1: 25m | AA1: 26m | AB1: 27m | AC1: 28m | AD1: 29m | AE1: 30m | AF1: 31m | AG1: 32m | AH1: 33m | AI1: 34m | AJ1: 35m | AK1: 36m | AL1: 37m | AM1: 38m | AN1: 39m | AO1: 40m | AP1: 41m | AQ1: 42m | AR1: 43m | AS1: 44m | AT1: 45m | AU1: 46m | AV1: 47m | AW1: 48m | AX1: 49m | AY1: 50m | AZ1: 51m | BA1: 52m | BB1: 53m | BC1: 54m | BD1: 55m | BE1: 56m | BF1: 57m | BG1: 58m | BH1: 59m | BI1: 60m
A2: {=TRANSPOSE(B1:BI1)} -> 1m | B2: {=[2]!MCovar('Q3 Returns'!B2:BI253)} -> 4.9625076 | C2: 3.9750805 | D2: 3.5221939 | E2: 3.2461607 | F2: 3.078534 | G2: 2.9805002 | H2: 2.9214273 | I2: 2.8760925 | J2: 2.8313018 | K2: 2.7815788 | L2: 2.7256895 | M2: 2.6648208 | N2: 2.6012668 | O2: 2.537 | P2: 2.4733195 | Q2: 2.4111462 | R2: 2.3511187 | S2: 2.2936668 | T2: 2.2390508 | U2: 2.187378 | V2: 2.1386414 | W2: 2.0927541 | X2: 2.0495812 | Y2: 2.008962 | Z2: 1.9707202 | AA2: 1.93467 | AB2: 1.9006288 | AC2: 1.8684283 | AD2: 1.8379176 | AE2: 1.8089597 | AF2: 1.7814292 | AG2: 1.7552098 | AH2: 1.7301923 | AI2: 1.7062757 | AJ2: 1.6833688 | AK2: 1.6613905 | AL2: 1.640268 | AM2: 1.6199357 | AN2: 1.6003336 | AO2: 1.5814077 | AP2: 1.5631087 | AQ2: 1.5453923 | AR2: 1.5282184 | AS2: 1.5115506 | AT2: 1.4953562 | AU2: 1.4796053 | AV2: 1.4642707 | AW2: 1.4493278 | AX2: 1.4347542 | AY2: 1.4205298 | AZ2: 1.406636 | BA2: 1.3930563 | BB2: 1.3797755 | BC2: 1.36678 | BD2: 1.3540572 | BE2: 1.3415956 | BF2: 1.3293846 | BG2: 1.3174144 | BH2: 1.3056763 | BI2: 1.2941626
A3: 2m | B3: 3.9750805 | C3: 4.2452657 | D3: 4.4427319 | E3: 4.4881766 | F3: 4.4351856 | G3: 4.3377151 | H3: 4.2332809 | I3: 4.1379439 | J3: 4.0554491 | K3: 3.9842989 | L3: 3.9217026 | M3: 3.865776 | N3: 3.8151721 | O3: 3.7687365 | P3: 3.7255669 | Q3: 3.6850395 | R3: 3.6467335 | S3: 3.6103301 | T3: 3.5755833 | U3: 3.5422959 | V3: 3.5102875 | W3: 3.4793926 | X3: 3.4494751 | Y3: 3.420426 | Z3: 3.392147 | AA3: 3.3645448 | AB3: 3.3375323 | AC3: 3.3110361 | AD3: 3.2849972 | AE3: 3.2593687 | AF3: 3.2341128 | AG3: 3.2091982 | AH3: 3.1845964 | AI3: 3.1602819 | AJ3: 3.1362331 | AK3: 3.1124333 | AL3: 3.0888695 | AM3: 3.0655316 | AN3: 3.0424113 | AO3: 3.0195018 | AP3: 2.9967973 | AQ3: 2.9742934 | AR3: 2.951987 | AS3: 2.9298762 | AT3: 2.90796 | AU3: 2.8862379 | AV3: 2.8647102 | AW3: 2.8433772 | AX3: 2.82224 | AY3: 2.8012995 | AZ3: 2.7805575 | BA3: 2.7600154 | BB3: 2.7396755 | BC3: 2.7195398 | BD3: 2.6996108 | BE3: 2.6798908 | BF3: 2.6603817 | BG3: 2.6410853 | BH3: 2.6220037 | BI3: 2.603139
A4: 3m | B4: 3.5221939 | C4: 4.4427319 | D4: 5.1787436 | E4: 5.5693995 | F4: 5.6808815 | G4: 5.6254011 | H4: 5.501457 | I4: 5.3682103 | J4: 5.2498717 | K4: 5.1527129 | L4: 5.075557 | M4: 5.0154555 | N4: 4.9685999 | O4: 4.9312589 | P4: 4.9005802 | Q4: 4.8745084 | R4: 4.8515767 | S4: 4.8306866 | T4: 4.811027 | U4: 4.7920236 | V4: 4.773252 | W4: 4.7543991 | X4: 4.7352568 | Y4: 4.715702 | Z4: 4.6956601 | AA4: 4.6750872 | AB4: 4.6539565 | AC4: 4.6322593 | AD4: 4.6100019 | AE4: 4.587202 | AF4: 4.5638868 | AG4: 4.5400893 | AH4: 4.5158443 | AI4: 4.4911871 | AJ4: 4.4661528 | AK4: 4.4407774 | AL4: 4.4150973 | AM4: 4.3891486 | AN4: 4.3629663 | AO4: 4.3365833 | AP4: 4.3100309 | AQ4: 4.283339 | AR4: 4.2565363 | AS4: 4.2296503 | AT4: 4.2027077 | AU4: 4.1757339 | AV4: 4.1487533 | AW4: 4.1217884 | AX4: 4.0948607 | AY4: 4.0679907 | AZ4: 4.0411973 | BA4: 4.0144991 | BB4: 3.9879132 | BC4: 3.9614564 | BD4: 3.9351446 | BE4: 3.9089924 | BF4: 3.8830131 | BG4: 3.8572193 | BH4: 3.8316229 | BI4: 3.8062352
A5: 4m | B5: 3.2461607 | C5: 4.4881766 | D5: 5.5693995 | E5: 6.2206986 | F5: 6.4851628 | G5: 6.4993971 | H5: 6.3966057 | I5: 6.2634412 | J5: 6.138737 | K5: 6.0357393 | L5: 5.9561136 | M5: 5.8974856 | N5: 5.8553359 | O5: 5.8248662 | P5: 5.8023766 | Q5: 5.7851736 | R5: 5.7713055 | S5: 5.759305 | T5: 5.7480915 | U5: 5.736912 | V5: 5.7252297 | W5: 5.7126678 | X5: 5.6989899 | Y5: 5.684073 | Z5: 5.6678658 | AA5: 5.650363 | AB5: 5.6315822 | AC5: 5.6115605 | AD5: 5.5903486 | AE5: 5.568007 | AF5: 5.5446042 | AG5: 5.5202142 | AH5: 5.4949116 | AI5: 5.4687702 | AJ5: 5.441861 | AK5: 5.4142532 | AL5: 5.3860138 | AM5: 5.3572078 | AN5: 5.3278969 | AO5: 5.2981391 | AP5: 5.2679885 | AQ5: 5.2374964 | AR5: 5.2067112 | AS5: 5.1756789 | AT5: 5.1444433 | AU5: 5.113046 | AV5: 5.0815263 | AW5: 5.0499206 | AX5: 5.0182636 | AY5: 4.9865874 | AZ5: 4.9549223 | BA5: 4.9232971 | BB5: 4.8917388 | BC5: 4.8602732 | BD5: 4.8289245 | BE5: 4.7977152 | BF5: 4.7666659 | BG5: 4.7357957 | BH5: 4.705123 | BI5: 4.674665
A6: 5m | B6: 3.078534 | C6: 4.4351856 | D6: 5.6808815 | E6: 6.4851628 | F6: 6.8669545 | G6: 6.9640729 | H6: 6.9187034 | I6: 6.8270017 | J6: 6.7340337 | K6: 6.6568749 | L6: 6.5994182 | M6: 6.5603931 | N6: 6.5357142 | O6: 6.5207368 | P6: 6.5118989 | Q6: 6.506643 | R6: 6.5031413 | S6: 6.5000431 | T6: 6.4963802 | U6: 6.4915094 | V6: 6.4850007 | W6: 6.4765801 | X6: 6.4661064 | Y6: 6.4535454 | Z6: 6.4389295 | AA6: 6.4223338 | AB6: 6.4038488 | AC6: 6.3835768 | AD6: 6.3616263 | AE6: 6.3381092 | AF6: 6.31314 | AG6: 6.2868338 | AH6: 6.2593031 | AI6: 6.2306561 | AJ6: 6.2009947 | AK6: 6.1704157 | AL6: 6.1390109 | AM6: 6.1068676 | AN6: 6.0740678 | AO6: 6.0406878 | AP6: 6.0067987 | AQ6: 5.9724665 | AR6: 5.9377535 | AS6: 5.9027182 | AT6: 5.8674159 | AU6: 5.8318985 | AV6: 5.796215 | AW6: 5.7604107 | AX6: 5.7245281 | AY6: 5.6886068 | AZ6: 5.6526839 | BA6: 5.6167941 | BB6: 5.5809702 | BC6: 5.5452432 | BD6: 5.5096421 | BE6: 5.4741936 | BF6: 5.4389222 | BG6: 5.4038508 | BH6: 5.369001 | BI6: 5.3343931
A7: 6m | B7: 2.9805002 | C7: 4.3377151 | D7: 5.6254011 | E7: 6.4993971 | F7: 6.9640729 | G7: 7.1466806 | H7: 7.1814459 | I7: 7.1610674 | J7: 7.1301322 | K7: 7.1063766 | L7: 7.0946419 | M7: 7.0945495 | N7: 7.1028564 | O7: 7.1156871 | P7: 7.1301753 | Q7: 7.1443795 | R7: 7.1570063 | S7: 7.1671689 | T7: 7.1743018 | U7: 7.1781037 | V7: 7.1784393 | W7: 7.1752903 | X7: 7.1687359 | Y7: 7.1589286 | Z7: 7.146061 | AA7: 7.130346 | AB7: 7.1119927 | AC7: 7.0912054 | AD7: 7.0681806 | AE7: 7.0431061 | AF7: 7.0161622 | AG7: 6.9875212 | AH7: 6.9573453 | AI7: 6.9257862 | AJ7: 6.892984 | AK7: 6.8590686 | AL7: 6.8241611 | AM7: 6.7883741 | AN7: 6.7518123 | AO7: 6.714572 | AP7: 6.6767417 | AQ7: 6.6384033 | AR7: 6.5996329 | AS7: 6.5605012 | AT7: 6.5210746 | AU7: 6.4814147 | AV7: 6.441579 | AW7: 6.4016207 | AX7: 6.3615891 | AY7: 6.3215301 | AZ7: 6.281486 | BA7: 6.2414965 | BB7: 6.2015987 | BC7: 6.1618273 | BD7: 6.1222147 | BE7: 6.0827905 | BF7: 6.0435817 | BG7: 6.0046135 | BH7: 5.9659096 | BI7: 5.9274918
A8: 7m | B8: 2.9214273 | C8: 4.2332809 | D8: 5.501457 | E8: 6.3966057 | F8: 6.9187034 | G8: 7.1814459 | H8: 7.3038352 | I8: 7.368743 | J8: 7.4164437 | K8: 7.4630521 | L8: 7.5130583 | M8: 7.5663782 | N8: 7.6204455 | O8: 7.6722083 | P8: 7.7196218 | Q8: 7.7615138 | R8: 7.7972888 | S8: 7.8266808 | T8: 7.8496718 | U8: 7.8664305 | V8: 7.8772277 | W8: 7.8823995 | X8: 7.8823328 | Y8: 7.8774418 | Z8: 7.8681408 | AA8: 7.8548316 | AB8: 7.8378848 | AC8: 7.817643 | AD8: 7.7944217 | AE8: 7.7685119 | AF8: 7.7401836 | AG8: 7.7096864 | AH8: 7.6772496 | AI8: 7.6430829 | AJ8: 7.6073772 | AK8: 7.5703064 | AL8: 7.53203 | AM8: 7.4926946 | AN8: 7.4524342 | AO8: 7.411371 | AP8: 7.3696165 | AQ8: 7.3272728 | AR8: 7.2844338 | AS8: 7.241186 | AT8: 7.1976094 | AU8: 7.1537778 | AV8: 7.1097597 | AW8: 7.0656175 | AX8: 7.0214092 | AY8: 6.9771878 | AZ8: 6.9330023 | BA8: 6.888898 | BB8: 6.8449171 | BC8: 6.8010986 | BD8: 6.7574785 | BE8: 6.7140897 | BF8: 6.6709621 | BG8: 6.628123 | BH8: 6.5855984 | BI8: 6.5434116
A9: 8m | B9: 2.8760925 | C9: 4.1379439 | D9: 5.3682103 | E9: 6.2634412 | F9: 6.8270017 | G9: 7.1610674 | H9: 7.368743 | I9: 7.5215756 | J9: 7.6540244 | K9: 7.779215 | L9: 7.9002057 | M9: 8.0164879 | N9: 8.1256938 | O9: 8.2253044 | P9: 8.3139406 | Q9: 8.3911307 | R9: 8.4569642 | S9: 8.5118132 | T9: 8.5562409 | U9: 8.59093 | V9: 8.616605 | W9: 8.6340071 | X9: 8.643882 | Y9: 8.6469547 | Z9: 8.6439051 | AA9: 8.6353633 | AB9: 8.6218965 | AC9: 8.6040164 | AD9: 8.5821854 | AE9: 8.5568229 | AF9: 8.5283107 | AG9: 8.4969967 | AH9: 8.4631948 | AI9: 8.4271892 | AJ9: 8.3892355 | AK9: 8.3495643 | AL9: 8.3083852 | AM9: 8.2658884 | AN9: 8.2222464 | AO9: 8.1776155 | AP9: 8.1321374 | AQ9: 8.0859406 | AR9: 8.0391427 | AS9: 7.9918511 | AT9: 7.9441643 | AU9: 7.8961726 | AV9: 7.8479585 | AW9: 7.7995978 | AX9: 7.7511595 | AY9: 7.7027069 | AZ9: 7.6542979 | BA9: 7.6059857 | BB9: 7.5578192 | BC9: 7.5098435 | BD9: 7.4621 | BE9: 7.4146261 | BF9: 7.3674556 | BG9: 7.3206195 | BH9: 7.2741464 | BI9: 7.2280624
A10: 9m | B10: 2.8313018 | C10: 4.0554491 | D10: 5.2498717 | E10: 6.138737 | F10: 6.7340337 | G10: 7.1301322 | H10: 7.4164437 | I10: 7.6540244 | J10: 7.871292 | K10: 8.0776658 | L10: 8.2739875 | M10: 8.4586812 | N10: 8.6290469 | O10: 8.7827051 | P10: 8.9186881 | Q10: 9.0370675 | R10: 9.1385267 | S10: 9.2240238 | T10: 9.2946793 | U10: 9.3516851 | V10: 9.3962287 | W10: 9.4294734 | X10: 9.4525486 | Y10: 9.466517 | Z10: 9.4723512 | AA10: 9.470936 | AB10: 9.463059 | AC10: 9.4494236 | AD10: 9.4306599 | AE10: 9.4073342 | AF10: 9.3799583 | AG10: 9.3489942 | AH10: 9.3148559 | AI10: 9.2779149 | AJ10: 9.2385038 | AK10: 9.1969213 | AL10: 9.1534367 | AM10: 9.1082929 | AN10: 9.0617093 | AO10: 9.0138834 | AP10: 8.9649937 | AQ10: 8.9152015 | AR10: 8.8646534 | AS10: 8.8134828 | AT10: 8.7618111 | AU10: 8.7097491 | AV10: 8.6573977 | AW10: 8.6048487 | AX10: 8.5521858 | AY10: 8.4994851 | AZ10: 8.4468161 | BA10: 8.394242 | BB10: 8.3418208 | BC10: 8.2896057 | BD10: 8.2376449 | BE10: 8.185982 | BF10: 8.1346562 | BG10: 8.0837033 | BH10: 8.033156 | BI10: 7.9830441
A11: 10m | B11: 2.7815788 | C11: 3.9842989 | D11: 5.1527129 | E11: 6.0357393 | F11: 6.6568749 | G11: 7.1063766 | H11: 7.4630521 | I11: 7.779215 | J11: 8.0776658 | K11: 8.3638694 | L11: 8.6359784 | M11: 8.8908778 | N11: 9.1250841 | O11: 9.3359932 | P11: 9.5227943 | Q11: 9.6859285 | R11: 9.8265559 | S11: 9.9461401 | T11: 10.046305 | U11: 10.128721 | V11: 10.195021 | W11: 10.246784 | X11: 10.285526 | Y11: 10.312655 | Z11: 10.329447 | AA11: 10.337054 | AB11: 10.336495 | AC11: 10.328678 | AD11: 10.314411 | AE11: 10.294419 | AF11: 10.269354 | AG11: 10.239803 | AH11: 10.206287 | AI11: 10.169276 | AJ11: 10.129186 | AK11: 10.086392 | AL11: 10.04123 | AM11: 9.9940012 | AN11: 9.9449775 | AO11: 9.8944033 | AP11: 9.8424985 | AQ11: 9.7894614 | AR11: 9.7354719 | AS11: 9.6806927 | AT11: 9.6252718 | AU11: 9.5693435 | AV11: 9.5130298 | AW11: 9.4564415 | AX11: 9.3996791 | AY11: 9.3428339 | AZ11: 9.2859887 | BA11: 9.229219 | BB11: 9.1725934 | BC11: 9.1161744 | BD11: 9.060019 | BE11: 9.0041782 | BF11: 8.9486978 | BG11: 8.8936193 | BH11: 8.8389809 | BI11: 8.7848167
A12: 11m | B12: 2.7256895 | C12: 3.9217026 | D12: 5.075557 | E12: 5.9561136 | F12: 6.5994182 | G12: 7.0946419 | H12: 7.5130583 | I12: 7.9002057 | J12: 8.2739875 | K12: 8.6359784 | L12: 8.9814347 | M12: 9.3054111 | N12: 9.6033129 | O12: 9.8720217 | P12: 10.110668 | Q12: 10.319904 | R12: 10.501247 | S12: 10.65658 | T12: 10.787963 | U12: 10.897496 | V12: 10.987225 | W12: 11.059126 | X12: 11.115084 | Y12: 11.156847 | Z12: 11.18599 | AA12: 11.20393 | AB12: 11.211923 | AC12: 11.211079 | AD12: 11.202391 | AE12: 11.186743 | AF12: 11.164931 | AG12: 11.137669 | AH12: 11.105594 | AI12: 11.069273 | AJ12: 11.029213 | AK12: 10.985865 | AL12: 10.939637 | AM12: 10.890892 | AN12: 10.839957 | AO12: 10.787126 | AP12: 10.732662 | AQ12: 10.676804 | AR12: 10.619767 | AS12: 10.561745 | AT12: 10.502914 | AU12: 10.443434 | AV12: 10.383451 | AW12: 10.323095 | AX12: 10.262485 | AY12: 10.201728 | AZ12: 10.140924 | BA12: 10.08016 | BB12: 10.019517 | BC12: 9.9590671 | BD12: 9.8988778 | BE12: 9.8390083 | BF12: 9.7795117 | BG12: 9.7204363 | BH12: 9.661826 | BI12: 9.6037202
A13: 12m | B13: 2.6648208 | C13: 3.865776 | D13: 5.0154555 | E13: 5.8974856 | F13: 6.5603931 | G13: 7.0945495 | H13: 7.5663782 | I13: 8.0164879 | J13: 8.4586812 | K13: 8.8908778 | L13: 9.3054111 | M13: 9.695361 | N13: 10.054813 | O13: 10.379925 | P13: 10.669601 | Q13: 10.924569 | R13: 11.1466 | S13: 11.337907 | T13: 11.500922 | U13: 11.638121 | V13: 11.751924 | W13: 11.844667 | X13: 11.918586 | Y13: 11.975748 | Z13: 12.018016 | AA13: 12.047063 | AB13: 12.064372 | AC13: 12.071256 | AD13: 12.068882 | AE13: 12.058294 | AF13: 12.040431 | AG13: 12.016132 | AH13: 11.986146 | AI13: 11.951142 | AJ13: 11.911714 | AK13: 11.868394 | AL13: 11.821657 | AM13: 11.771931 | AN13: 11.719599 | AO13: 11.665004 | AP13: 11.608455 | AQ13: 11.55023 | AR13: 11.49058 | AS13: 11.429732 | AT13: 11.367891 | AU13: 11.305244 | AV13: 11.241959 | AW13: 11.178188 | AX13: 11.114069 | AY13: 11.049727 | AZ13: 10.985275 | BA13: 10.920815 | BB13: 10.856441 | BC13: 10.792237 | BD13: 10.728278 | BE13: 10.664634 | BF13: 10.601366 | BG13: 10.538529 | BH13: 10.476172 | BI13: 10.414342
A14: 13m | B14: 2.6012668 | C14: 3.8151721 | D14: 4.9685999 | E14: 5.8553359 | F14: 6.5357142 | G14: 7.1028564 | H14: 7.6204455 | I14: 8.1256938 | J14: 8.6290469 | K14: 9.1250841 | L14: 9.6033129 | M14: 10.054813 | N14: 10.472249 | O14: 10.85093 | P14: 11.189414 | Q14: 11.488403 | R14: 11.749832 | S14: 11.97617 | T14: 12.170156 | U14: 12.334593 | V14: 12.472229 | W14: 12.585729 | X14: 12.677644 | Y14: 12.75034 | Z14: 12.805946 | AA14: 12.846379 | AB14: 12.873334 | AC14: 12.888315 | AD14: 12.892657 | AE14: 12.887557 | AF14: 12.874087 | AG14: 12.85321 | AH14: 12.825782 | AI14: 12.792569 | AJ14: 12.75425 | AK14: 12.711434 | AL14: 12.664666 | AM14: 12.614433 | AN14: 12.561173 | AO14: 12.505279 | AP14: 12.447102 | AQ14: 12.386962 | AR14: 12.325143 | AS14: 12.261906 | AT14: 12.197483 | AU14: 12.132088 | AV14: 12.065911 | AW14: 11.999127 | AX14: 11.931891 | AY14: 11.864347 | AZ14: 11.796622 | BA14: 11.728833 | BB14: 11.661085 | BC14: 11.593473 | BD14: 11.526085 | BE14: 11.458997 | BF14: 11.392279 | BG14: 11.325994 | BH14: 11.260197 | BI14: 11.194941
... A61: 60m | B61: 1.2941626 | C61: 2.603139 | D61: 3.8062352 | E61: 4.674665 | F61: 5.3343931 | G61: 5.9274918 | H61: 6.5434116 | I61: 7.2280624 | J61: 7.9830441 | K61: 8.7848167 | L61: 9.6037202 | M61: 10.414342 | N61: 11.194941 | O61: 11.929972 | P61: 12.611255 | Q61: 13.235625 | R61: 13.803052 | S61: 14.31519 | T61: 14.774729 | U61: 15.184978 | V61: 15.549562 | W61: 15.872266 | X61: 16.156909 | Y61: 16.40716 | Z61: 16.626419 | AA61: 16.817802 | AB61: 16.984116 | AC61: 17.127875 | AD61: 17.251334 | AE61: 17.356527 | AF61: 17.445297 | AG61: 17.519308 | AH61: 17.580058 | AI61: 17.628894 | AJ61: 17.667024 | AK61: 17.695535 | AL61: 17.7154 | AM61: 17.727497 | AN61: 17.732618 | AO61: 17.731473 | AP61: 17.724708 | AQ61: 17.712901 | AR61: 17.696581 | AS61: 17.676223 | AT61: 17.652261 | AU61: 17.625089 | AV61: 17.595064 | AW61: 17.562511 | AX61: 17.527726 | AY61: 17.490975 | AZ61: 17.452504 | BA61: 17.412532 | BB61: 17.371262 | BC61: 17.328876 | BD61: 17.285543 | BE61: 17.241415 | BF61: 17.196626 | BG61: 17.151302 | BH61: 17.105555 | BI61: 17.059488

Sheet Q3 PCA
B2: 1m | C2: 2m | D2: 3m | E2: 4m | F2: 5m | G2: 6m | H2: 7m | I2: 8m | J2: 9m | K2: 10m | L2: 11m | M2: 12m | N2: 13m | O2: 14m | P2: 15m | Q2: 16m | R2: 17m | S2: 18m | T2: 19m | U2: 20m | V2: 21m | W2: 22m | X2: 23m | Y2: 24m | Z2: 25m | AA2: 26m | AB2: 27m | AC2: 28m | AD2: 29m | AE2: 30m | AF2: 31m | AG2: 32m | AH2: 33m | AI2: 34m | AJ2: 35m | AK2: 36m | AL2: 37m | AM2: 38m | AN2: 39m | AO2: 40m | AP2: 41m | AQ2: 42m | AR2: 43m | AS2: 44m | AT2: 45m | AU2: 46m | AV2: 47m | AW2: 48m | AX2: 49m | AY2: 50m | AZ2: 51m | BA2: 52m | BB2: 53m | BC2: 54m | BD2: 55m | BE2: 56m | BF2: 57m | BG2: 58m | BH2: 59m | BI2: 60m
A3: Eigenvalues | B3: {=[2]!MEigenvalPow(_xlfn.ANCHORARRAY('Q3 Covariance'!B2))} -> 856.82287 | C3: 45.299972 | D3: 9.1526705 | E3: 4.1837194 | F3: 1.4441 | G3: 0.30876132 | H3: 0.052775001 | I3: 0.0062176963 | J3: 0.0011587544 | K3: 0.00018958756 | L3: 4.3792975e-05 | M3: 2.4222184e-05 | N3: 1.3160421e-05 | O3: 3.0484529e-06 | P3: 1.5039671e-06 | Q3: 5.6837527e-07 | R3: 2.8761829e-07 | S3: 1.2373162e-07 | T3: 8.6776049e-08 | U3: 2.553482e-08 | V3: 1.4675289e-08 | W3: 5.8116446e-09 | X3: 2.3226374e-09 | Y3: 1.2188893e-09 | Z3: 5.5393489e-10 | AA3: 3.802185e-10 | AB3: 2.2892166e-10 | AC3: 1.0067074e-10 | AD3: 6.2012008e-11 | AE3: 4.1160028e-11 | AF3: 2.5264637e-11 | AG3: 1.3976404e-11 | AH3: 9.5594479e-12 | AI3: 6.9360415e-12 | AJ3: 4.7425083e-12 | AK3: 2.8684612e-12 | AL3: 1.3818546e-12 | AM3: 1.128489e-12 | AN3: 6.7030469e-13 | AO3: 3.5665073e-13 | AP3: 1.96742e-13 | AQ3: 7.6283216e-14 | AR3: 6.5662525e-14 | AS3: 6.2627474e-14 | AT3: -5.6835528e-14 | AU3: -4.3234383e-14 | AV3: 3.8391478e-14 | AW3: -3.3755056e-14 | AX3: 3.1080081e-14 | AY3: 2.7992666e-14 | AZ3: 2.4955382e-14 | BA3: -2.1108015e-14 | BB3: 1.8710276e-14 | BC3: 1.657409e-14 | BD3: -1.3458739e-14 | BE3: -1.1154249e-14 | BF3: -9.4497484e-15 | BG3: 8.6124983e-15 | BH3: 3.2759243e-16 | BI3: 6.6666357e-16
A4: Percentage Explained | B4: =B3/SUM($B$3:$BI$3) -> 0.93409848 | C4: =C3/SUM($B$3:$BI$3) -> 0.049385511 | D4: =D3/SUM($B$3:$BI$3) -> 0.0099781365 | E4: =E3/SUM($B$3:$BI$3) -> 0.004561043 | F4: =F3/SUM($B$3:$BI$3) -> 0.0015743413 | G4: =G3/SUM($B$3:$BI$3) -> 0.00033660806 | H4: =H3/SUM($B$3:$BI$3) -> 5.7534702e-05 | I4: =I3/SUM($B$3:$BI$3) -> 6.7784613e-06 | ... BI4: =BI3/SUM($B$3:$BI$3) -> 7.2678899e-19
A5: Cumulative Percentage Explained | B5: =B4 -> 0.93409848 | C5: =B5+C4 -> 0.98348399 | D5: =C5+D4 -> 0.99346213 | E5: =D5+E4 -> 0.99802317 | F5: =E5+F4 -> 0.99959751 | G5: =F5+G4 -> 0.99993412 | H5: =G5+H4 -> 0.99999166 | I5: =H5+I4 -> 0.99999844 | J5: =I5+J4 -> 0.9999997 | ... BI5: =BH5+BI4 -> 1
A7: Eigenvector | B7: w1 | C7: w2 | D7: w3 | E7: w4 | F7: w5 | G7: w6 | H7: w7 | I7: w8 | J7: w9 | K7: w10 | L7: w11 | M7: w12 | N7: w13 | O7: w14 | P7: w15 | Q7: w16 | R7: w17 | S7: w18 | T7: w19 | U7: w20 | V7: w21 | W7: w22 | X7: w23 | Y7: w24 | Z7: w25 | AA7: w26 | AB7: w27 | AC7: w28 | AD7: w29 | AE7: w30 | AF7: w31 | AG7: w32 | AH7: w33 | AI7: w34 | AJ7: w35 | AK7: w36 | AL7: w37 | AM7: w38 | AN7: w39 | AO7: w40 | AP7: w41 | AQ7: w42 | AR7: w43 | AS7: w44 | AT7: w45 | AU7: w46 | AV7: w47 | AW7: w48 | AX7: w49 | AY7: w50 | AZ7: w51 | BA7: w52 | BB7: w53 | BC7: w54 | BD7: w55 | BE7: w56 | BF7: w57 | BG7: w58 | BH7: w59 | BI7: w60
A8: {=TRANSPOSE(B7:BI7)} -> w1 | B8: {=[2]!MEigenvecPow(_xlfn.ANCHORARRAY('Q3 Covariance'!B2),TRUE)} -> 0.016084546 | C8: 0.19408697 | D8: 0.22549674 | E8: 0.75431 | F8: 0.28964615 | G8: 0.4613467 | H8: 0.17304629 | I8: 0.1095822 | J8: 0.054941547 | K8: 0.021153431 | L8: 0.0087229766 | M8: 0.00032759951 | N8: 0.0018404318 | O8: 0 | P8: 0 | Q8: 0 | R8: 0 | S8: 0 | T8: 0 | U8: 0 | V8: 0 | W8: 0 | X8: 0 | Y8: 0 | Z8: 0 | AA8: 0 | AB8: 0 | AC8: 0 | AD8: 0 | AE8: 0 | AF8: 0 | AG8: 0 | AH8: 0 | AI8: 0 | AJ8: 0 | AK8: 0 | AL8: 0 | AM8: 0 | AN8: 0 | AO8: 0 | AP8: 0 | AQ8: 0 | AR8: 0 | AS8: 0 | AT8: 0 | AU8: 0 | AV8: 0 | AW8: 0 | AX8: 0 | AY8: 0 | AZ8: 0 | BA8: 0 | BB8: 0 | BC8: 0 | BD8: 0 | BE8: 0 | BF8: 0 | BG8: 0 | BH8: 0 | BI8: 0
A9: w2 | B9: 0.027964798 | C9: 0.225648 | D9: 0.24529224 | E9: 0.38549698 | F9: -0.10935904 | G9: -0.47231497 | H9: -0.40799872 | I9: -0.43300381 | J9: -0.32699899 | K9: -0.17737971 | L9: -0.098807488 | M9: -0.0060142857 | N9: -0.039900742 | O9: 0 | P9: 0 | Q9: 0 | R9: 0 | S9: 0 | T9: 0 | U9: 0 | V9: 0 | W9: 0 | X9: 0 | Y9: 0 | Z9: 0 | AA9: 0 | AB9: 0 | AC9: 0 | AD9: 0 | AE9: 0 | AF9: 0 | AG9: 0 | AH9: 0 | AI9: 0 | AJ9: 0 | AK9: 0 | AL9: 0 | AM9: 0 | AN9: 0 | AO9: 0 | AP9: 0 | AQ9: 0 | AR9: 0 | AS9: 0 | AT9: 0 | AU9: 0 | AV9: 0 | AW9: 0 | AX9: 0 | AY9: 0 | AZ9: 0 | BA9: 0 | BB9: 0 | BC9: 0 | BD9: 0 | BE9: 0 | BF9: 0 | BG9: 0 | BH9: 0 | BI9: 0
A10: w3 | B10: 0.038917075 | C10: 0.25806962 | D10: 0.26622996 | E10: 0.10844326 | F10: -0.29127325 | G10: -0.37290067 | H10: -0.0093843941 | I10: 0.26418815 | J10: 0.43653612 | K10: 0.41348375 | L10: 0.35618537 | M10: 0.041867849 | N10: 0.21852886 | O10: 0 | P10: 0 | Q10: 0 | R10: 0 | S10: 0 | T10: 0 | U10: 0 | V10: 0 | W10: 0 | X10: 0 | Y10: 0 | Z10: 0 | AA10: 0 | AB10: 0 | AC10: 0 | AD10: 0 | AE10: 0 | AF10: 0 | AG10: 0 | AH10: 0 | AI10: 0 | AJ10: 0 | AK10: 0 | AL10: 0 | AM10: 0 | AN10: 0 | AO10: 0 | AP10: 0 | AQ10: 0 | AR10: 0 | AS10: 0 | AT10: 0 | AU10: 0 | AV10: 0 | AW10: 0 | AX10: 0 | AY10: 0 | AZ10: 0 | BA10: 0 | BB10: 0 | BC10: 0 | BD10: 0 | BE10: 0 | BF10: 0 | BG10: 0 | BH10: 0 | BI10: 0
A11: w4 | B11: 0.046961627 | C11: 0.28016292 | D11: 0.25682728 | E11: -0.081308585 | F11: -0.3099493 | G11: -0.073718177 | H11: 0.23941201 | I11: 0.30377197 | J11: 0.11867237 | K11: -0.1826259 | L11: -0.41835274 | M11: -0.097351462 | N11: -0.47378293 | O11: 0 | P11: 0 | Q11: 0 | R11: 0 | S11: 0 | T11: 0 | U11: 0 | V11: 0 | W11: 0 | X11: 0 | Y11: 0 | Z11: 0 | AA11: 0 | AB11: 0 | AC11: 0 | AD11: 0 | AE11: 0 | AF11: 0 | AG11: 0 | AH11: 0 | AI11: 0 | AJ11: 0 | AK11: 0 | AL11: 0 | AM11: 0 | AN11: 0 | AO11: 0 | AP11: 0 | AQ11: 0 | AR11: 0 | AS11: 0 | AT11: 0 | AU11: 0 | AV11: 0 | AW11: 0 | AX11: 0 | AY11: 0 | AZ11: 0 | BA11: 0 | BB11: 0 | BC11: 0 | BD11: 0 | BE11: 0 | BF11: 0 | BG11: 0 | BH11: 0 | BI11: 0
A12: w5 | B12: 0.053114643 | C12: 0.28927817 | D12: 0.21811977 | E12: -0.18206846 | F12: -0.22785367 | G12: 0.14433814 | H12: 0.24871073 | I12: 0.068529351 | J12: -0.24896293 | K12: -0.32309572 | L12: -0.14417191 | M12: 0.028691935 | N12: 0.30961995 | O12: 0 | P12: 0 | Q12: 0 | R12: 0 | S12: 0 | T12: 0 | U12: 0 | V12: 0 | W12: 0 | X12: 0 | Y12: 0 | Z12: 0 | AA12: 0 | AB12: 0 | AC12: 0 | AD12: 0 | AE12: 0 | AF12: 0 | AG12: 0 | AH12: 0 | AI12: 0 | AJ12: 0 | AK12: 0 | AL12: 0 | AM12: 0 | AN12: 0 | AO12: 0 | AP12: 0 | AQ12: 0 | AR12: 0 | AS12: 0 | AT12: 0 | AU12: 0 | AV12: 0 | AW12: 0 | AX12: 0 | AY12: 0 | AZ12: 0 | BA12: 0 | BB12: 0 | BC12: 0 | BD12: 0 | BE12: 0 | BF12: 0 | BG12: 0 | BH12: 0 | BI12: 0
A13: w6 | B13: 0.058560128 | C13: 0.28745733 | D13: 0.16150938 | E13: -0.21492211 | F13: -0.10326002 | G13: 0.23330089 | H13: 0.11805967 | I13: -0.14819743 | J13: -0.27638239 | K13: -0.021224868 | L13: 0.32778905 | M13: 0.12803894 | N13: 0.3195768 | O13: 0 | P13: 0 | Q13: 0 | R13: 0 | S13: 0 | T13: 0 | U13: 0 | V13: 0 | W13: 0 | X13: 0 | Y13: 0 | Z13: 0 | AA13: 0 | AB13: 0 | AC13: 0 | AD13: 0 | AE13: 0 | AF13: 0 | AG13: 0 | AH13: 0 | AI13: 0 | AJ13: 0 | AK13: 0 | AL13: 0 | AM13: 0 | AN13: 0 | AO13: 0 | AP13: 0 | AQ13: 0 | AR13: 0 | AS13: 0 | AT13: 0 | AU13: 0 | AV13: 0 | AW13: 0 | AX13: 0 | AY13: 0 | AZ13: 0 | BA13: 0 | BB13: 0 | BC13: 0 | BD13: 0 | BE13: 0 | BF13: 0 | BG13: 0 | BH13: 0 | BI13: 0
A14: w7 | B14: 0.064041703 | C14: 0.27804662 | D14: 0.10014332 | E14: -0.20675315 | F14: 0.019450306 | G14: 0.22719446 | H14: -0.036227692 | I14: -0.24261191 | J14: -0.10226976 | K14: 0.22585042 | L14: 0.29995565 | M14: 0.025724277 | N14: -0.29202721 | O14: 0 | P14: 0 | Q14: 0 | R14: 0 | S14: 0 | T14: 0 | U14: 0 | V14: 0 | W14: 0 | X14: 0 | Y14: 0 | Z14: 0 | AA14: 0 | AB14: 0 | AC14: 0 | AD14: 0 | AE14: 0 | AF14: 0 | AG14: 0 | AH14: 0 | AI14: 0 | AJ14: 0 | AK14: 0 | AL14: 0 | AM14: 0 | AN14: 0 | AO14: 0 | AP14: 0 | AQ14: 0 | AR14: 0 | AS14: 0 | AT14: 0 | AU14: 0 | AV14: 0 | AW14: 0 | AX14: 0 | AY14: 0 | AZ14: 0 | BA14: 0 | BB14: 0 | BC14: 0 | BD14: 0 | BE14: 0 | BF14: 0 | BG14: 0 | BH14: 0 | BI14: 0
A15: w8 | B15: 0.069948807 | C15: 0.2636526 | D15: 0.042409205 | E15: -0.17898577 | F15: 0.11537251 | G15: 0.17243861 | H15: -0.14688292 | I15: -0.22094649 | J15: 0.082773791 | K15: 0.25823954 | L15: -0.013620047 | M15: -0.13011651 | N15: -0.37601595 | O15: 0 | P15: 0 | Q15: 0 | R15: 0 | S15: 0 | T15: 0 | U15: 0 | V15: 0 | W15: 0 | X15: 0 | Y15: 0 | Z15: 0 | AA15: 0 | AB15: 0 | AC15: 0 | AD15: 0 | AE15: 0 | AF15: 0 | AG15: 0 | AH15: 0 | AI15: 0 | AJ15: 0 | AK15: 0 | AL15: 0 | AM15: 0 | AN15: 0 | AO15: 0 | AP15: 0 | AQ15: 0 | AR15: 0 | AS15: 0 | AT15: 0 | AU15: 0 | AV15: 0 | AW15: 0 | AX15: 0 | AY15: 0 | AZ15: 0 | BA15: 0 | BB15: 0 | BC15: 0 | BD15: 0 | BE15: 0 | BF15: 0 | BG15: 0 | BH15: 0 | BI15: 0
A16: w9 | B16: 0.076311569 | C16: 0.24608886 | D16: -0.0082102653 | E16: -0.14382964 | F16: 0.17809747 | G16: 0.099661358 | H16: -0.19831037 | I16: -0.12813368 | J16: 0.19695152 | K16: 0.14809457 | L16: -0.27534879 | M16: -0.18703491 | N16: 0.043623041 | O16: 0 | P16: 0 | Q16: 0 | R16: 0 | S16: 0 | T16: 0 | U16: 0 | V16: 0 | W16: 0 | X16: 0 | Y16: 0 | Z16: 0 | AA16: 0 | AB16: 0 | AC16: 0 | AD16: 0 | AE16: 0 | AF16: 0 | AG16: 0 | AH16: 0 | AI16: 0 | AJ16: 0 | AK16: 0 | AL16: 0 | AM16: 0 | AN16: 0 | AO16: 0 | AP16: 0 | AQ16: 0 | AR16: 0 | AS16: 0 | AT16: 0 | AU16: 0 | AV16: 0 | AW16: 0 | AX16: 0 | AY16: 0 | AZ16: 0 | BA16: 0 | BB16: 0 | BC16: 0 | BD16: 0 | BE16: 0 | BF16: 0 | BG16: 0 | BH16: 0 | BI16: 0
A17: w10 | B17: 0.082953806 | C17: 0.22674175 | D17: -0.050665803 | E17: -0.10802763 | F17: 0.21068674 | G17: 0.02791482 | H17: -0.19964581 | I17: -0.014341882 | J17: 0.22455371 | K17: -0.0043851206 | L17: -0.31290936 | M17: -0.090046622 | N17: 0.3654664 | O17: 0 | P17: 0 | Q17: 0 | R17: 0 | S17: 0 | T17: 0 | U17: 0 | V17: 0 | W17: 0 | X17: 0 | Y17: 0 | Z17: 0 | AA17: 0 | AB17: 0 | AC17: 0 | AD17: 0 | AE17: 0 | AF17: 0 | AG17: 0 | AH17: 0 | AI17: 0 | AJ17: 0 | AK17: 0 | AL17: 0 | AM17: 0 | AN17: 0 | AO17: 0 | AP17: 0 | AQ17: 0 | AR17: 0 | AS17: 0 | AT17: 0 | AU17: 0 | AV17: 0 | AW17: 0 | AX17: 0 | AY17: 0 | AZ17: 0 | BA17: 0 | BB17: 0 | BC17: 0 | BD17: 0 | BE17: 0 | BF17: 0 | BG17: 0 | BH17: 0 | BI17: 0
A18: w11 | B18: 0.089646908 | C18: 0.20664385 | D18: -0.084994989 | E18: -0.075092095 | F18: 0.21944912 | G18: -0.032018529 | H18: -0.16727189 | I18: 0.081780973 | J18: 0.17896498 | K18: -0.14180699 | L18: -0.14311644 | M18: 0.11687824 | N18: 0.26089978 | O18: 0 | P18: 0 | Q18: 0 | R18: 0 | S18: 0 | T18: 0 | U18: 0 | V18: 0 | W18: 0 | X18: 0 | Y18: 0 | Z18: 0 | AA18: 0 | AB18: 0 | AC18: 0 | AD18: 0 | AE18: 0 | AF18: 0 | AG18: 0 | AH18: 0 | AI18: 0 | AJ18: 0 | AK18: 0 | AL18: 0 | AM18: 0 | AN18: 0 | AO18: 0 | AP18: 0 | AQ18: 0 | AR18: 0 | AS18: 0 | AT18: 0 | AU18: 0 | AV18: 0 | AW18: 0 | AX18: 0 | AY18: 0 | AZ18: 0 | BA18: 0 | BB18: 0 | BC18: 0 | BD18: 0 | BE18: 0 | BF18: 0 | BG18: 0 | BH18: 0 | BI18: 0
A19: w12 | B19: 0.096197289 | C19: 0.18653732 | D19: -0.11178705 | E19: -0.04644559 | F19: 0.21064176 | G19: -0.076197324 | H19: -0.11588656 | I19: 0.14379338 | J19: 0.09152322 | K19: -0.22313667 | L19: 0.087178968 | M19: 0.28937756 | N19: -0.068896185 | O19: 0 | P19: 0 | Q19: 0 | R19: 0 | S19: 0 | T19: 0 | U19: 0 | V19: 0 | W19: 0 | X19: 0 | Y19: 0 | Z19: 0 | AA19: 0 | AB19: 0 | AC19: 0 | AD19: 0 | AE19: 0 | AF19: 0 | AG19: 0 | AH19: 0 | AI19: 0 | AJ19: 0 | AK19: 0 | AL19: 0 | AM19: 0 | AN19: 0 | AO19: 0 | AP19: 0 | AQ19: 0 | AR19: 0 | AS19: 0 | AT19: 0 | AU19: 0 | AV19: 0 | AW19: 0 | AX19: 0 | AY19: 0 | AZ19: 0 | BA19: 0 | BB19: 0 | BC19: 0 | BD19: 0 | BE19: 0 | BF19: 0 | BG19: 0 | BH19: 0 | BI19: 0
A20: w13 | B20: 0.102442 | C20: 0.16697076 | D20: -0.13198332 | E20: -0.02228869 | F20: 0.19015215 | G20: -0.10502475 | H20: -0.058146692 | I20: 0.17151765 | J20: 0.0014022549 | K20: -0.21848181 | L20: 0.19839177 | M20: 0.26105689 | N20: -0.21061159 | O20: 0 | P20: 0 | Q20: 0 | R20: 0 | S20: 0 | T20: 0 | U20: 0 | V20: 0 | W20: 0 | X20: 0 | Y20: 0 | Z20: 0 | AA20: 0 | AB20: 0 | AC20: 0 | AD20: 0 | AE20: 0 | AF20: 0 | AG20: 0 | AH20: 0 | AI20: 0 | AJ20: 0 | AK20: 0 | AL20: 0 | AM20: 0 | AN20: 0 | AO20: 0 | AP20: 0 | AQ20: 0 | AR20: 0 | AS20: 0 | AT20: 0 | AU20: 0 | AV20: 0 | AW20: 0 | AX20: 0 | AY20: 0 | AZ20: 0 | BA20: 0 | BB20: 0 | BC20: 0 | BD20: 0 | BE20: 0 | BF20: 0 | BG20: 0 | BH20: 0 | BI20: 0
... A67: w60 | B67: 0.13776 | C67: -0.097446315 | D67: 0.18079133 | E67: -0.057404571 | F67: 0.18229575 | G67: -0.12480745 | H67: 0.22421148 | I67: -0.20159468 | J67: 0.18735767 | K67: -0.19411795 | L67: 0.13961028 | M67: -0.26382669 | N67: -0.0058627363 | O67: 0 | P67: 0 | Q67: 0 | R67: 0 | S67: 0 | T67: 0 | U67: 0 | V67: 0 | W67: 0 | X67: 0 | Y67: 0 | Z67: 0 | AA67: 0 | AB67: 0 | AC67: 0 | AD67: 0 | AE67: 0 | AF67: 0 | AG67: 0 | AH67: 0 | AI67: 0 | AJ67: 0 | AK67: 0 | AL67: 0 | AM67: 0 | AN67: 0 | AO67: 0 | AP67: 0 | AQ67: 0 | AR67: 0 | AS67: 0 | AT67: 0 | AU67: 0 | AV67: 0 | AW67: 0 | AX67: 0 | AY67: 0 | AZ67: 0 | BA67: 0 | BB67: 0 | BC67: 0 | BD67: 0 | BE67: 0 | BF67: 0 | BG67: 0 | BH67: 0 | BI67: 0

Sheet Q3 PC VaR
B1: PV01 | C1: w1 | D1: w2 | E1: w3
A2: 1m | B2: 0.59752862 | C2: {='Q3 PCA'!B8:D67} -> 0.016084546 | D2: 0.19408697 | E2: 0.22549674 | H2: PC1 | I2: PC2 | J2: PC3
A3: 2m | B3: 0.21709062 | C3: 0.027964798 | D3: 0.225648 | E3: 0.24529224 | G3: Net sensitivities | H3: {=MMULT(TRANSPOSE(B2:B61),_xlfn.ANCHORARRAY(C2))*1000} -> 428.148 | I3: -2974.5856 | J3: 1041.2108
A4: 3m | B4: 0.23420338 | C4: 0.038917075 | D4: 0.25806962 | E4: 0.26622996
A5: 4m | B5: -1.587742 | C5: 0.046961627 | D5: 0.28016292 | E5: 0.25682728 | G5: Eigenvalues | H5: ='Q3 PCA'!B3 -> 856.82287 | I5: 0 | J5: 0
A6: 5m | B6: -1.7811979 | C6: 0.053114643 | D6: 0.28927817 | E6: 0.21811977 | H6: 0 | I6: ='Q3 PCA'!C3 -> 45.299972 | J6: 0
A7: 6m | B7: 0.69419226 | C7: 0.058560128 | D7: 0.28745733 | E7: 0.16150938 | H7: 0 | I7: 0 | J7: ='Q3 PCA'!D3 -> 9.1526705
A8: 7m | B8: -2.9815561 | C8: 0.064041703 | D8: 0.27804662 | E8: 0.10014332
A9: 8m | B9: -0.57158519 | C9: 0.069948807 | D9: 0.2636526 | E9: 0.042409205
A10: 9m | B10: -1.8145941 | C10: 0.076311569 | D10: 0.24608886 | E10: -0.0082102653 | G10: q'Wq | H10: {=MMULT(_xlfn.ANCHORARRAY(H3),MMULT(H5:J7,TRANSPOSE(_xlfn.ANCHORARRAY(H3))))} -> 5.6780878e+08
A11: 10m | B11: 0.31637601 | C11: 0.082953806 | D11: 0.22674175 | E11: -0.050665803 | G11: VaR | H11: =SQRT(H10*10)*_xlfn.NORM.S.INV(0.99) -> 175297.49
A12: 11m | B12: 0.81908764 | C12: 0.089646908 | D12: 0.20664385 | E12: -0.084994989
A13: 12m | B13: 0.5 | C13: 0.096197289 | D13: 0.18653732 | E13: -0.11178705
A14: 13m | B14: -1.3442214 | C14: 0.102442 | D14: 0.16697076 | E14: -0.13198332
A15: 14m | B15: 0.19394765 | C15: 0.10826691 | D15: 0.14829809 | E15: -0.14660837
A16: 15m | B16: 0.059015201 | C16: 0.11361551 | D16: 0.13070588 | E16: -0.15657827
A17: 16m | B17: -0.78153615 | C17: 0.11847029 | D17: 0.11427421 | E17: -0.16267877
A18: 17m | B18: 0.12354304 | C18: 0.12283774 | D18: 0.099016096 | E18: -0.1655785
A19: 18m | B19: -1.6912556 | C19: 0.12673684 | D19: 0.084905953 | E19: -0.165843
A20: 19m | B20: -1.1544393 | C20: 0.13019402 | D20: 0.071895287 | E20: -0.16395181
A21: 20m | B21: 0.16620292 | C21: 0.13323976 | D21: 0.059921467 | E21: -0.16029907
A22: 21m | B22: -0.32017051 | C22: 0.13590636 | D22: 0.048912809 | E22: -0.15521066
A23: 22m | B23: -1.0112389 | C23: 0.13822679 | D23: 0.038792415 | E23: -0.14896
... A61: 60m | B61: 0.2 | C61: 0.13776 | D61: -0.097446315 | E61: 0.18079133

Sheet Q4 a)
B3: Information | E3: Risk Factors | H3: Volatilities (Yearly)
B4: Portfolio ($) | C4: 2000000 | E4: Beta | F4: 1.5 | H4: FTSE 100 | I4: 0.15
B5: alpha | C5: 0.01 | E5: Currency | F5: 1 | H5: $/£ | I5: 0.2
H6: Correlation | I6: 0.3
B8: Covariance Matrix (Yearly)
C9: {=TRANSPOSE(B10:B11)} -> FTSE 100 | D9: $/£
B10: FTSE 100 | C10: =I4^2 -> 0.0225 | D10: =I4*I5*I6 -> 0.009
B11: $/£ | C11: =D10 -> 0.009 | D11: =I5^2 -> 0.04
B13: Covariance Matrix (10-day)
C14: {=TRANSPOSE(B15:B16)} -> FTSE 100 | D14: $/£
B15: FTSE 100 | C15: {=(C10:D11)*(10/250)} -> 0.0009 | D15: 0.00036
B16: $/£ | C16: 0.00036 | D16: 0.0016
B18: Systematic and Stand-Alone VaR
B20: 10-day Systematic VaR | E20: 10-day Equity VaR | H20: 10-day Forex VaR
B21: q'Wq | C21: {=MMULT(TRANSPOSE(F4:F5),MMULT(_xlfn.ANCHORARRAY(C15),F4:F5))} -> 0.004705 | E21: q'Wq | F21: =F4*C15*F4 -> 0.002025 | H21: q'Wq | I21: =F5*D16*F5 -> 0.0016
B22: NormInv | C22: =_xlfn.NORM.S.INV(1-$C$5) -> 2.3263479 | E22: NormInv | F22: =_xlfn.NORM.S.INV(1-$C$5) -> 2.3263479 | H22: NormInv | I22: =_xlfn.NORM.S.INV(1-$C$5) -> 2.3263479
B23: 10-day VaR (%) | C23: =C22*SQRT(C21) -> 0.15957119 | E23: 10-day VaR (%) | F23: =F22*SQRT(F21) -> 0.10468565 | H23: 10-day VaR (%) | I23: =I22*SQRT(I21) -> 0.093053915
B24: 10-day VaR ($) | C24: =C23*$C$4 -> 319142.37 | E24: 10-day VaR ($) | F24: =F23*$C$4 -> 209371.31 | H24: 10-day VaR ($) | I24: =I23*$C$4 -> 186107.83
B26: Sum of Stand-Alone VaRs
B27: =F24+I24 -> 395479.14
B30: Marginal VaR
C31: Wq | D31: g(q)
B32: FTSE 100 | C32: {=MMULT(_xlfn.ANCHORARRAY(C15),F4:F5)} -> 0.00171 | D32: =C32*_xlfn.NORM.S.INV(1-$C$5)/SQRT($C$21) -> 0.057995054
B33: $/£ | C33: 0.00214 | D33: =C33*_xlfn.NORM.S.INV(1-$C$5)/SQRT($C$21) -> 0.072578605
B35: Equity Marginal VaR (%) | C35: =D32*F4 -> 0.086992581
B36: Equity Marginal VaR ($) | C36: =C35*$C$4 -> 173985.16
B37: Forex Marginal VaR (%) | C37: =D33*F5 -> 0.072578605
B38: Forex Marginal VaR ($) | C38: =C37*$C$4 -> 145157.21
B39: Sum of Marginal VaRs | C39: =C36+C38 -> 319142.37
B72: Graphing Quanto Correlation vs Systematic VaR | E72: Equity | F72: Forex | G72: Sum
B73: -1 | C73: 23263.479 | E73: 209371.31 | F73: 186107.83 | G73: 395479.14
B74: -0.75 | C74: 141506.22 | E74: 209371.31 | F74: 186107.83 | G74: 395479.14
B75: -0.5 | C75: 198763.25 | E75: 209371.31 | F75: 186107.83 | G75: 395479.14
B76: -0.25 | C76: 242877.85 | E76: 209371.31 | F76: 186107.83 | G76: 395479.14
B77: 0 | C77: 280129.38 | E77: 209371.31 | F77: 186107.83 | G77: 395479.14
B78: 0.25 | C78: 312978.1 | E78: 209371.31 | F78: 186107.83 | G78: 395479.14
B79: 0.3 | C79: 319142.37 | E79: 209371.31 | F79: 186107.83 | G79: 395479.14
B80: 0.5 | C80: 342692.44 | E80: 209371.31 | F80: 186107.83 | G80: 395479.14
B81: 0.75 | C81: 370028.28 | E81: 209371.31 | F81: 186107.83 | G81: 395479.14
B82: 1 | C82: 395479.14 | E82: 209371.31 | F82: 186107.83 | G82: 395479.14

Sheet Q4 b)
B1: Information | E1: alpha | F1: 0.01
K2: q
B3: Local Exposures | J3: S&P 500 | K3: 1800000
B4: Index | C4: Amount ($) | D4: Beta | E4: Return | F4: Vol | G4: Net dollar Beta | J4: FTSE 100 | K4: 2200000
B5: S&P 500 | C5: 2000000 | D5: 0.9 | E5: X1 | F5: 0.2 | G5: =C5*D5 -> 1800000 | J5: CAC 40 | K5: 3600000
B6: FTSE 100 | C6: 2000000 | D6: 1.1 | E6: X2 | F6: 0.22 | G6: =C6*D6 -> 2200000 | J6: DAX 30 | K6: 5200000
B7: CAC 40 | C7: 3000000 | D7: 1.2 | E7: X3 | F7: 0.25 | G7: =C7*D7 -> 3600000 | J7: $/£ | K7: 2000000
B8: DAX 30 | C8: 4000000 | D8: 1.3 | E8: X4 | F8: 0.27 | G8: =C8*D8 -> 5200000 | J8: $/€ | K8: 7000000
B10: Forex Exposures
B11: Exposure | C11: Return | D11: Vol | E11: Amount ($)
B12: $/£ | C12: X5 | D12: 0.15 | E12: 2000000
B13: $/€ | C13: X6 | D13: 0.1 | E13: 7000000
B16: Correlation Matrix
C17: {=TRANSPOSE(B18:B23)} -> S&P 500 | D17: FTSE 100 | E17: CAC 40 | F17: DAX 30 | G17: $/£ | H17: $/€
B18: S&P 500 | C18: 1 | D18: 0.75 | E18: 0.75 | F18: 0.75 | G18: 0.2 | H18: 0.2
B19: FTSE 100 | C19: 0.75 | D19: 1 | E19: 0.75 | F19: 0.75 | G19: 0.2 | H19: 0.2
B20: CAC 40 | C20: 0.75 | D20: 0.75 | E20: 1 | F20: 0.75 | G20: 0.2 | H20: 0.2
B21: DAX 30 | C21: 0.75 | D21: 0.75 | E21: 0.75 | F21: 1 | G21: 0.2 | H21: 0.2
B22: $/£ | C22: 0.2 | D22: 0.2 | E22: 0.2 | F22: 0.2 | G22: 1 | H22: 0.5
B23: $/€ | C23: 0.2 | D23: 0.2 | E23: 0.2 | F23: 0.2 | G23: 0.5 | H23: 1
B26: Covariance Matrix (Annual)
B27: Vol | D27: {=TRANSPOSE(B29:B34)} -> 0.2 | E27: 0.22 | F27: 0.25 | G27: 0.27 | H27: 0.15 | I27: 0.1
D28: S&P 500 | E28: FTSE 100 | F28: CAC 40 | G28: DAX 30 | H28: $/£ | I28: $/€
B29: 0.2 | C29: S&P 500 | D29: =$B29*D$27 -> 0.04 | E29: =$B29*E$27*D18 -> 0.033 | F29: =$B29*F$27*E18 -> 0.0375 | G29: =$B29*G$27*F18 -> 0.0405 | H29: =$B29*H$27*G18 -> 0.006 | I29: =$B29*I$27*H18 -> 0.004
B30: 0.22 | C30: FTSE 100 | D30: {=TRANSPOSE(E29:I29)} -> 0.033 | E30: =$B30*E$27 -> 0.0484 | F30: =$B30*F$27*E19 -> 0.04125 | G30: =$B30*G$27*F19 -> 0.04455 | H30: =$B30*H$27*G19 -> 0.0066 | I30: =$B30*I$27*H19 -> 0.0044
B31: 0.25 | C31: CAC 40 | D31: 0.0375 | E31: {=TRANSPOSE(F30:I30)} -> 0.04125 | F31: =$B31*F$27 -> 0.0625 | G31: =$B31*G$27*F20 -> 0.050625 | H31: =$B31*H$27*G20 -> 0.0075 | I31: =$B31*I$27*H20 -> 0.005
B32: 0.27 | C32: DAX 30 | D32: 0.0405 | E32: 0.04455 | F32: {=TRANSPOSE(G31:I31)} -> 0.050625 | G32: =$B32*G$27 -> 0.0729 | H32: =$B32*H$27*G21 -> 0.0081 | I32: =$B32*I$27*H21 -> 0.0054
B33: 0.15 | C33: $/£ | D33: 0.006 | E33: 0.0066 | F33: 0.0075 | G33: {=TRANSPOSE(H32:I32)} -> 0.0081 | H33: =$B33*H$27 -> 0.0225 | I33: =$B33*I$27*H22 -> 0.0075
B34: 0.1 | C34: $/€ | D34: 0.004 | E34: 0.0044 | F34: 0.005 | G34: 0.0054 | H34: =I33 -> 0.0075 | I34: =$B34*I$27 -> 0.01
B37: Systematic and Stand-Alone VaR
B39: 1% 10 Day Systematic | E39: 1% 10 Day Equity | H39: 1% 10 Day Forex
B40: q'Wq | C40: {=MMULT(TRANSPOSE(K3:K8),MMULT(D29:I34,K3:K8))} -> 10267896000000 | E40: q'Wq | F40: {=MMULT(TRANSPOSE(K3:K6),MMULT(D29:G32,K3:K6))} -> 8218696000000 | H40: q'Wq | I40: {=MMULT(TRANSPOSE(K7:K8),MMULT(H33:I34,K7:K8))} -> 7.9e+11
B41: Norm Inv | C41: =_xlfn.NORM.S.INV(1-$F$1) -> 2.3263479 | E41: Norm Inv | F41: =_xlfn.NORM.S.INV(1-$F$1) -> 2.3263479 | H41: Norm Inv | I41: =_xlfn.NORM.S.INV(1-$F$1) -> 2.3263479
B42: VaR | C42: =C41*SQRT(C40)*SQRT(10/250) -> 1490889.3 | E42: VaR | F42: =F41*SQRT(F40)*SQRT(10/250) -> 1333847.3 | H42: VaR | I42: =I41*SQRT(I40)*SQRT(10/250) -> 413540.64
B44: Sum of Stand-Alones
B45: =F42+I42 -> 1747387.9
B47: Marginal VaR
C48: Wq | D48: g(q)
B49: S&P 500 | C49: {=MMULT(D29:I34,K3:K8)} -> 530200 | D49: =C49*_xlfn.NORM.S.INV(1-$F$1)/SQRT($C$40) -> 0.38492281
B50: FTSE 100 | C50: 590040 | D50: =C50*_xlfn.NORM.S.INV(1-$F$1)/SQRT($C$40) -> 0.42836638
...

Sheet Q5
B2: Mixture Parameters | I2: t-dist Parameters
C3: p | D3: μ1 | E3: μ2 | F3: σ1 | G3: σ2 | J3: df | K3: μ | L3: σ
B4: ALSI | C4: 0.35522483 | D4: -0.00077459 | E4: 0.00078161 | F4: =SQRT(0.000247948999) -> 0.015746396 | G4: =SQRT(0.0000487674198) -> 0.0069833674 | I4: ALSI | J4: 4.2943522 | K4: 0.00022880862 | L4: 0.010914184
B5: TOP40 | C5: 0.3566325 | D5: -0.0007205 | E5: 0.00075729 | F5: =SQRT(0.000275564762) -> 0.016600143 | G5: =SQRT(0.0000566977803) -> 0.0075297928 | I5: TOP40 | J5: 4.5785571 | K5: 0.00023025916 | L5: 0.011588895
B6: INDI25 | C6: 0.38922774 | D6: -0.00103481 | E6: 0.00114812 | F6: =SQRT(0.000262833222) -> 0.016212132 | G6: =SQRT(0.0000641540438) -> 0.008009622 | I6: INDI25 | J6: 3.9916227 | K6: 0.00029846282 | L6: 0.011902501
C9: Mixture VaR | D9: t-dist VaR | F9: VaR Parameters
B10: ALSI | C10: 0.030830868 | D10: =TINV($G$10*2,J4)*SQRT(((J4-2)/J4)*$G$11)*L4-K4*$G$11 -> 0.029662853 | F10: Significance Level | G10: 0.01
B11: TOP40 | C11: 0.032436046 | D11: =TINV($G$10*2,J5)*SQRT(((J5-2)/J5)*$G$11)*L5-K5*$G$11 -> 0.032356689 | F11: Risk Horizon | G11: 1
B12: INDI25 | C12: 0.032625543 | D12: =TINV($G$10*2,J6)*SQRT(((J6-2)/J6)*$G$11)*L6-K6*$G$11 -> 0.03787751
B18: Objective for calculating Mixture VaR
B19: Objective | C19: =G10-(C6*NORMSDIST((-C20-D6)/F6)+(1-C6)*NORMSDIST((-C20-E6)/G6)) -> 6.7938155e-12
B20: Mixture VaR | C20: 0.032625543
